2019-10-19 14:23:09,866 ERROR: Exception on / [GET] [in e:\google_drive\3.projects\0.luan_van\embedded_code\venv\lib\site-packages\flask\app.py:1891]
Traceback (most recent call last):
  File "e:\google_drive\3.projects\0.luan_van\embedded_code\venv\lib\site-packages\flask\app.py", line 2446, in wsgi_app
    response = self.full_dispatch_request()
  File "e:\google_drive\3.projects\0.luan_van\embedded_code\venv\lib\site-packages\flask\app.py", line 1951, in full_dispatch_request
    rv = self.handle_user_exception(e)
  File "e:\google_drive\3.projects\0.luan_van\embedded_code\venv\lib\site-packages\flask\app.py", line 1820, in handle_user_exception
    reraise(exc_type, exc_value, tb)
  File "e:\google_drive\3.projects\0.luan_van\embedded_code\venv\lib\site-packages\flask\_compat.py", line 39, in reraise
    raise value
  File "e:\google_drive\3.projects\0.luan_van\embedded_code\venv\lib\site-packages\flask\app.py", line 1949, in full_dispatch_request
    rv = self.dispatch_request()
  File "e:\google_drive\3.projects\0.luan_van\embedded_code\venv\lib\site-packages\flask\app.py", line 1935, in dispatch_request
    return self.view_functions[rule.endpoint](**req.view_args)
  File "E:\Google_Drive\3.Projects\0.LUAN_VAN\Embedded_Code\seperate_components\saveInfoServer\app\save_info\routes.py", line 40, in index
    return render_template('save_info/index.html', **templateData)
  File "e:\google_drive\3.projects\0.luan_van\embedded_code\venv\lib\site-packages\flask\templating.py", line 140, in render_template
    ctx.app,
  File "e:\google_drive\3.projects\0.luan_van\embedded_code\venv\lib\site-packages\flask\templating.py", line 120, in _render
    rv = template.render(context)
  File "e:\google_drive\3.projects\0.luan_van\embedded_code\venv\lib\site-packages\jinja2\asyncsupport.py", line 76, in render
    return original_render(self, *args, **kwargs)
  File "e:\google_drive\3.projects\0.luan_van\embedded_code\venv\lib\site-packages\jinja2\environment.py", line 1008, in render
    return self.environment.handle_exception(exc_info, True)
  File "e:\google_drive\3.projects\0.luan_van\embedded_code\venv\lib\site-packages\jinja2\environment.py", line 780, in handle_exception
    reraise(exc_type, exc_value, tb)
  File "e:\google_drive\3.projects\0.luan_van\embedded_code\venv\lib\site-packages\jinja2\_compat.py", line 37, in reraise
    raise value.with_traceback(tb)
  File "E:\Google_Drive\3.Projects\0.LUAN_VAN\Embedded_Code\seperate_components\saveInfoServer\app\templates\save_info\index.html", line 3, in top-level template code
    {% from "_formhelper.html" import render_button %}
  File "e:\google_drive\3.projects\0.luan_van\embedded_code\venv\lib\site-packages\flask\templating.py", line 60, in get_source
    return self._get_source_fast(environment, template)
  File "e:\google_drive\3.projects\0.luan_van\embedded_code\venv\lib\site-packages\flask\templating.py", line 89, in _get_source_fast
    raise TemplateNotFound(template)
jinja2.exceptions.TemplateNotFound: _formhelper.html
2019-10-19 14:25:39,283 ERROR: Exception on / [POST] [in e:\google_drive\3.projects\0.luan_van\embedded_code\venv\lib\site-packages\flask\app.py:1891]
Traceback (most recent call last):
  File "e:\google_drive\3.projects\0.luan_van\embedded_code\venv\lib\site-packages\flask\app.py", line 2446, in wsgi_app
    response = self.full_dispatch_request()
  File "e:\google_drive\3.projects\0.luan_van\embedded_code\venv\lib\site-packages\flask\app.py", line 1951, in full_dispatch_request
    rv = self.handle_user_exception(e)
  File "e:\google_drive\3.projects\0.luan_van\embedded_code\venv\lib\site-packages\flask\app.py", line 1820, in handle_user_exception
    reraise(exc_type, exc_value, tb)
  File "e:\google_drive\3.projects\0.luan_van\embedded_code\venv\lib\site-packages\flask\_compat.py", line 39, in reraise
    raise value
  File "e:\google_drive\3.projects\0.luan_van\embedded_code\venv\lib\site-packages\flask\app.py", line 1949, in full_dispatch_request
    rv = self.dispatch_request()
  File "e:\google_drive\3.projects\0.luan_van\embedded_code\venv\lib\site-packages\flask\app.py", line 1935, in dispatch_request
    return self.view_functions[rule.endpoint](**req.view_args)
  File "E:\Google_Drive\3.Projects\0.LUAN_VAN\Embedded_Code\seperate_components\saveInfoServer\app\save_info\routes.py", line 33, in index
    return redirect(url_for('save_info.gotInfo'))
  File "e:\google_drive\3.projects\0.luan_van\embedded_code\venv\lib\site-packages\flask\helpers.py", line 370, in url_for
    return appctx.app.handle_url_build_error(error, endpoint, values)
  File "e:\google_drive\3.projects\0.luan_van\embedded_code\venv\lib\site-packages\flask\app.py", line 2215, in handle_url_build_error
    reraise(exc_type, exc_value, tb)
  File "e:\google_drive\3.projects\0.luan_van\embedded_code\venv\lib\site-packages\flask\_compat.py", line 39, in reraise
    raise value
  File "e:\google_drive\3.projects\0.luan_van\embedded_code\venv\lib\site-packages\flask\helpers.py", line 358, in url_for
    endpoint, values, method=method, force_external=external
  File "e:\google_drive\3.projects\0.luan_van\embedded_code\venv\lib\site-packages\werkzeug\routing.py", line 2020, in build
    raise BuildError(endpoint, values, method, self)
werkzeug.routing.BuildError: Could not build url for endpoint 'save_info.gotInfo'. Did you mean 'gotInfo' instead?
